[2025-01-05T17:42:42.330+0000] {local_task_job_runner.py:123} INFO - ::group::Pre task execution logs
[2025-01-05T17:42:42.343+0000] {taskinstance.py:2613} INFO - Dependencies all met for dep_context=non-requeueable deps ti=<TaskInstance: user_processing2_vsc.store_user scheduled__2025-01-05T17:41:00+00:00 [queued]>
[2025-01-05T17:42:42.350+0000] {taskinstance.py:2613} INFO - Dependencies all met for dep_context=requeueable deps ti=<TaskInstance: user_processing2_vsc.store_user scheduled__2025-01-05T17:41:00+00:00 [queued]>
[2025-01-05T17:42:42.350+0000] {taskinstance.py:2866} INFO - Starting attempt 1 of 1
[2025-01-05T17:42:42.361+0000] {taskinstance.py:2889} INFO - Executing <Task(PythonOperator): store_user> on 2025-01-05 17:41:00+00:00
[2025-01-05T17:42:42.368+0000] {warnings.py:112} WARNING - /home/***/.local/lib/python3.12/site-packages/***/task/task_runner/standard_task_runner.py:70: DeprecationWarning: This process (pid=4891) is multi-threaded, use of fork() may lead to deadlocks in the child.
  pid = os.fork()

[2025-01-05T17:42:42.369+0000] {standard_task_runner.py:72} INFO - Started process 4893 to run task
[2025-01-05T17:42:42.370+0000] {standard_task_runner.py:104} INFO - Running: ['***', 'tasks', 'run', 'user_processing2_vsc', 'store_user', 'scheduled__2025-01-05T17:41:00+00:00', '--job-id', '192', '--raw', '--subdir', 'DAGS_FOLDER/user_dag.py', '--cfg-path', '/tmp/tmpcubrz6xz']
[2025-01-05T17:42:42.371+0000] {standard_task_runner.py:105} INFO - Job 192: Subtask store_user
[2025-01-05T17:42:42.413+0000] {task_command.py:467} INFO - Running <TaskInstance: user_processing2_vsc.store_user scheduled__2025-01-05T17:41:00+00:00 [running]> on host cab0b5f06594
[2025-01-05T17:42:42.655+0000] {taskinstance.py:3132} INFO - Exporting env vars: AIRFLOW_CTX_DAG_OWNER='***' AIRFLOW_CTX_DAG_ID='user_processing2_vsc' AIRFLOW_CTX_TASK_ID='store_user' AIRFLOW_CTX_EXECUTION_DATE='2025-01-05T17:41:00+00:00' AIRFLOW_CTX_TRY_NUMBER='1' AIRFLOW_CTX_DAG_RUN_ID='scheduled__2025-01-05T17:41:00+00:00'
[2025-01-05T17:42:42.656+0000] {logging_mixin.py:190} INFO - Task instance is in running state
[2025-01-05T17:42:42.656+0000] {logging_mixin.py:190} INFO -  Previous state of the Task instance: queued
[2025-01-05T17:42:42.656+0000] {logging_mixin.py:190} INFO - Current task name:store_user state:running start_date:2025-01-05 17:42:42.343869+00:00
[2025-01-05T17:42:42.656+0000] {logging_mixin.py:190} INFO - Dag name:user_processing2_vsc and current dag run status:running
[2025-01-05T17:42:42.657+0000] {taskinstance.py:731} INFO - ::endgroup::
[2025-01-05T17:42:42.657+0000] {logging_mixin.py:190} INFO - File exists!
[2025-01-05T17:42:42.657+0000] {logging_mixin.py:190} INFO - firstname,lastname,country,username,password,email
[2025-01-05T17:42:42.657+0000] {logging_mixin.py:190} INFO - Isabel,Armas,Mexico,heavyduck706,crystal,isabel.armas@example.com
[2025-01-05T17:42:42.657+0000] {postgres.py:204} INFO - Running copy expert: COPY users FROM stdin WITH DELIMITER as ',', filename: /tmp/processed_user.csv
[2025-01-05T17:42:42.666+0000] {base.py:84} INFO - Retrieving connection 'postgres'
[2025-01-05T17:42:42.669+0000] {taskinstance.py:3311} ERROR - Task failed with exception
Traceback (most recent call last):
  File "/home/airflow/.local/lib/python3.12/site-packages/airflow/models/taskinstance.py", line 767, in _execute_task
    result = _execute_callable(context=context, **execute_callable_kwargs)
             ^^^^^^^^^^^^^^^^^^^^^^^^^^^^^^^^^^^^^^^^^^^^^^^^^^^^^^^^^^^^^
  File "/home/airflow/.local/lib/python3.12/site-packages/airflow/models/taskinstance.py", line 733, in _execute_callable
    return ExecutionCallableRunner(
           ^^^^^^^^^^^^^^^^^^^^^^^^
  File "/home/airflow/.local/lib/python3.12/site-packages/airflow/utils/operator_helpers.py", line 252, in run
    return self.func(*args, **kwargs)
           ^^^^^^^^^^^^^^^^^^^^^^^^^^
  File "/home/airflow/.local/lib/python3.12/site-packages/airflow/models/baseoperator.py", line 422, in wrapper
    return func(self, *args, **kwargs)
           ^^^^^^^^^^^^^^^^^^^^^^^^^^^
  File "/home/airflow/.local/lib/python3.12/site-packages/airflow/operators/python.py", line 238, in execute
    return_value = self.execute_callable()
                   ^^^^^^^^^^^^^^^^^^^^^^^
  File "/home/airflow/.local/lib/python3.12/site-packages/airflow/operators/python.py", line 256, in execute_callable
    return runner.run(*self.op_args, **self.op_kwargs)
           ^^^^^^^^^^^^^^^^^^^^^^^^^^^^^^^^^^^^^^^^^^^
  File "/home/airflow/.local/lib/python3.12/site-packages/airflow/utils/operator_helpers.py", line 252, in run
    return self.func(*args, **kwargs)
           ^^^^^^^^^^^^^^^^^^^^^^^^^^
  File "/opt/airflow/dags/user_dag.py", line 51, in _store_user
    hook.copy_expert(
  File "/home/airflow/.local/lib/python3.12/site-packages/airflow/providers/postgres/hooks/postgres.py", line 210, in copy_expert
    cur.copy_expert(sql, file)
psycopg2.errors.UniqueViolation: duplicate key value violates unique constraint "users_pkey"
DETAIL:  Key (firstname)=(firstname) already exists.
CONTEXT:  COPY users, line 1

[2025-01-05T17:42:42.676+0000] {logging_mixin.py:190} INFO - Task instance in failure state
[2025-01-05T17:42:42.677+0000] {logging_mixin.py:190} INFO - Task start:2025-01-05 17:42:42.343869+00:00 end:2025-01-05 17:42:42.676486+00:00 duration:0.332617
[2025-01-05T17:42:42.677+0000] {logging_mixin.py:190} INFO - Task:<Task(PythonOperator): store_user> dag:<DAG: user_processing2_vsc> dagrun:<DagRun user_processing2_vsc @ 2025-01-05 17:41:00+00:00: scheduled__2025-01-05T17:41:00+00:00, state:running, queued_at: 2025-01-05 17:42:33.045149+00:00. externally triggered: False>
[2025-01-05T17:42:42.677+0000] {logging_mixin.py:190} INFO - Failure caused by duplicate key value violates unique constraint "users_pkey"
DETAIL:  Key (firstname)=(firstname) already exists.
CONTEXT:  COPY users, line 1
[2025-01-05T17:42:42.677+0000] {taskinstance.py:1225} INFO - Marking task as FAILED. dag_id=user_processing2_vsc, task_id=store_user, run_id=scheduled__2025-01-05T17:41:00+00:00, execution_date=20250105T174100, start_date=20250105T174242, end_date=20250105T174242
[2025-01-05T17:42:42.688+0000] {taskinstance.py:340} INFO - ::group::Post task execution logs
[2025-01-05T17:42:42.688+0000] {standard_task_runner.py:124} ERROR - Failed to execute job 192 for task store_user (duplicate key value violates unique constraint "users_pkey"
DETAIL:  Key (firstname)=(firstname) already exists.
CONTEXT:  COPY users, line 1
; 4893)
Traceback (most recent call last):
  File "/home/airflow/.local/lib/python3.12/site-packages/airflow/task/task_runner/standard_task_runner.py", line 117, in _start_by_fork
    ret = args.func(args, dag=self.dag)
          ^^^^^^^^^^^^^^^^^^^^^^^^^^^^^
  File "/home/airflow/.local/lib/python3.12/site-packages/airflow/cli/cli_config.py", line 49, in command
    return func(*args, **kwargs)
           ^^^^^^^^^^^^^^^^^^^^^
  File "/home/airflow/.local/lib/python3.12/site-packages/airflow/utils/cli.py", line 116, in wrapper
    return f(*args, **kwargs)
           ^^^^^^^^^^^^^^^^^^
  File "/home/airflow/.local/lib/python3.12/site-packages/airflow/cli/commands/task_command.py", line 483, in task_run
    task_return_code = _run_task_by_selected_method(args, _dag, ti)
                       ^^^^^^^^^^^^^^^^^^^^^^^^^^^^^^^^^^^^^^^^^^^^
  File "/home/airflow/.local/lib/python3.12/site-packages/airflow/cli/commands/task_command.py", line 256, in _run_task_by_selected_method
    return _run_raw_task(args, ti)
           ^^^^^^^^^^^^^^^^^^^^^^^
  File "/home/airflow/.local/lib/python3.12/site-packages/airflow/cli/commands/task_command.py", line 341, in _run_raw_task
    return ti._run_raw_task(
           ^^^^^^^^^^^^^^^^^
  File "/home/airflow/.local/lib/python3.12/site-packages/airflow/utils/session.py", line 97, in wrapper
    return func(*args, session=session, **kwargs)
           ^^^^^^^^^^^^^^^^^^^^^^^^^^^^^^^^^^^^^^
  File "/home/airflow/.local/lib/python3.12/site-packages/airflow/models/taskinstance.py", line 3005, in _run_raw_task
    return _run_raw_task(
           ^^^^^^^^^^^^^^
  File "/home/airflow/.local/lib/python3.12/site-packages/airflow/models/taskinstance.py", line 273, in _run_raw_task
    TaskInstance._execute_task_with_callbacks(
  File "/home/airflow/.local/lib/python3.12/site-packages/airflow/models/taskinstance.py", line 3159, in _execute_task_with_callbacks
    result = self._execute_task(context, task_orig)
             ^^^^^^^^^^^^^^^^^^^^^^^^^^^^^^^^^^^^^^
  File "/home/airflow/.local/lib/python3.12/site-packages/airflow/models/taskinstance.py", line 3183, in _execute_task
    return _execute_task(self, context, task_orig)
           ^^^^^^^^^^^^^^^^^^^^^^^^^^^^^^^^^^^^^^^
  File "/home/airflow/.local/lib/python3.12/site-packages/airflow/models/taskinstance.py", line 767, in _execute_task
    result = _execute_callable(context=context, **execute_callable_kwargs)
             ^^^^^^^^^^^^^^^^^^^^^^^^^^^^^^^^^^^^^^^^^^^^^^^^^^^^^^^^^^^^^
  File "/home/airflow/.local/lib/python3.12/site-packages/airflow/models/taskinstance.py", line 733, in _execute_callable
    return ExecutionCallableRunner(
           ^^^^^^^^^^^^^^^^^^^^^^^^
  File "/home/airflow/.local/lib/python3.12/site-packages/airflow/utils/operator_helpers.py", line 252, in run
    return self.func(*args, **kwargs)
           ^^^^^^^^^^^^^^^^^^^^^^^^^^
  File "/home/airflow/.local/lib/python3.12/site-packages/airflow/models/baseoperator.py", line 422, in wrapper
    return func(self, *args, **kwargs)
           ^^^^^^^^^^^^^^^^^^^^^^^^^^^
  File "/home/airflow/.local/lib/python3.12/site-packages/airflow/operators/python.py", line 238, in execute
    return_value = self.execute_callable()
                   ^^^^^^^^^^^^^^^^^^^^^^^
  File "/home/airflow/.local/lib/python3.12/site-packages/airflow/operators/python.py", line 256, in execute_callable
    return runner.run(*self.op_args, **self.op_kwargs)
           ^^^^^^^^^^^^^^^^^^^^^^^^^^^^^^^^^^^^^^^^^^^
  File "/home/airflow/.local/lib/python3.12/site-packages/airflow/utils/operator_helpers.py", line 252, in run
    return self.func(*args, **kwargs)
           ^^^^^^^^^^^^^^^^^^^^^^^^^^
  File "/opt/airflow/dags/user_dag.py", line 51, in _store_user
    hook.copy_expert(
  File "/home/airflow/.local/lib/python3.12/site-packages/airflow/providers/postgres/hooks/postgres.py", line 210, in copy_expert
    cur.copy_expert(sql, file)
psycopg2.errors.UniqueViolation: duplicate key value violates unique constraint "users_pkey"
DETAIL:  Key (firstname)=(firstname) already exists.
CONTEXT:  COPY users, line 1

[2025-01-05T17:42:42.724+0000] {local_task_job_runner.py:266} INFO - Task exited with return code 1
[2025-01-05T17:42:42.740+0000] {taskinstance.py:3895} INFO - 0 downstream tasks scheduled from follow-on schedule check
[2025-01-05T17:42:42.743+0000] {local_task_job_runner.py:245} INFO - ::endgroup::
